{
 "cells": [
  {
   "cell_type": "markdown",
   "id": "d12f0982-9637-42e6-adf0-84cc8ea4016a",
   "metadata": {},
   "source": [
    "Q-1. Explain why we have to use the Exception class while creating a Custom Exception.\n",
    "Note: Here Exception class refers to the base class for all the exceptions."
   ]
  },
  {
   "cell_type": "markdown",
   "id": "a4f58733-62ea-4edf-b6f8-eee678100f02",
   "metadata": {},
   "source": [
    "In Python, the `Exception` class serves as the base class for all built-in exceptions. When creating custom exceptions, it's recommended to inherit from the `Exception` class or one of its subclasses. Here's why:\n",
    "\n",
    "1. **Consistency and compatibility:** Inheriting from the `Exception` class ensures that your custom exception behaves like a standard exception in Python. This makes it compatible with existing exception-handling mechanisms such as `try-except` blocks, making your code more consistent and predictable.\n",
    "\n",
    "2. **Ease of use:** By inheriting from the `Exception` class, your custom exception inherits all the properties and methods of the base class. This includes attributes like `args` and methods like `__str__`, which are commonly used in exception handling.\n",
    "\n",
    "3. **Clarity and readability:** Using the `Exception` class as the base class for custom exceptions makes your code more readable and understandable to other developers. It clearly indicates that your custom exception is intended to represent an exceptional condition in the program.\n",
    "\n",
    "4. **Interoperability:** When you use the `Exception` class as the base class for your custom exception, it ensures interoperability with third-party libraries and frameworks that expect exceptions to be derived from the standard `Exception` hierarchy. This helps in maintaining compatibility and avoids potential conflicts.\n",
    "\n",
    "Overall, by adhering to the convention of inheriting from the `Exception` class when creating custom exceptions, you ensure that your exceptions integrate smoothly with the existing exception-handling infrastructure in Python and maintain consistency and compatibility across your codebase."
   ]
  },
  {
   "cell_type": "markdown",
   "id": "4d6bb3eb-284e-48bd-845e-48a5ca4b9d3f",
   "metadata": {},
   "source": [
    "Q-2. Write a pyhton program to print Python Exception Hierarchy."
   ]
  },
  {
   "cell_type": "code",
   "execution_count": 1,
   "id": "bfcb4c8f-6224-45d9-923b-24593e051d8c",
   "metadata": {},
   "outputs": [],
   "source": [
    "import logging\n",
    "\n",
    "# Configure logging\n",
    "logging.basicConfig(filename='exception_hierarchy.log', level=logging.INFO)\n",
    "\n",
    "def print_exception_hierarchy(exception_class, indent=0):\n",
    "    logging.info(' ' * indent + str(exception_class))\n",
    "    for subclass in exception_class.__subclasses__():\n",
    "        print_exception_hierarchy(subclass, indent + 4)\n",
    "\n",
    "def main():\n",
    "    try:\n",
    "        # Print Python Exception Hierarchy\n",
    "        logging.info(\"Python Exception Hierarchy:\")\n",
    "        print_exception_hierarchy(BaseException)\n",
    "    except Exception as e:\n",
    "        logging.exception(\"An error occurred while printing the exception hierarchy: {}\".format(e))\n",
    "\n",
    "if __name__ == \"__main__\":\n",
    "    main()\n"
   ]
  },
  {
   "cell_type": "markdown",
   "id": "985cd847-bfc4-44f6-a4e6-ed9d59e10da7",
   "metadata": {},
   "source": [
    "Q-3. What errors are defined in the ArithmeticError class? Explain any two with an example."
   ]
  },
  {
   "cell_type": "markdown",
   "id": "a1dcb512-cd1e-4ab4-95c0-32c035ec860c",
   "metadata": {},
   "source": [
    "The `ArithmeticError` class in Python defines several errors related to arithmetic operations. Here are the errors defined within the `ArithmeticError` class:\n",
    "\n",
    "1. **FloatingPointError**: This error occurs when a floating-point operation fails to produce a valid result. It typically arises from situations like overflow, underflow, or division by zero in floating-point arithmetic.\n",
    "\n",
    "2. **OverflowError**: This error occurs when the result of an arithmetic operation exceeds the representable range of the data type. For example, it may occur when performing arithmetic operations with integers that result in a value larger than the maximum representable integer.\n",
    "\n",
    "3. **ZeroDivisionError**: This error occurs when attempting to divide a number by zero. It indicates an invalid arithmetic operation where the divisor is zero.\n",
    "\n",
    "These errors are subclasses of the `ArithmeticError` class and represent specific types of arithmetic-related exceptions. They provide more specific information about the nature of the error that occurred during arithmetic operations.\n",
    "\n",
    "Sure, let's explore two arithmetic-related errors: `ZeroDivisionError` and `OverflowError`, along with examples demonstrating their occurrence and handling using the logging module.\n",
    "\n",
    "1. **ZeroDivisionError:**\n",
    "   - This error occurs when attempting to divide a number by zero.\n",
    "   - It indicates an invalid arithmetic operation where the divisor is zero.\n",
    "\n",
    "Example:\n",
    "\n",
    "import logging\n",
    "\n",
    "# Configure logging\n",
    "logging.basicConfig(filename='error.log', level=logging.ERROR)\n",
    "\n",
    "def divide_numbers(x, y):\n",
    "    try:\n",
    "        result = x / y\n",
    "        return result\n",
    "    except ZeroDivisionError as e:\n",
    "        logging.exception(\"Error occurred while dividing: {}\".format(e))\n",
    "        return None\n",
    "\n",
    "def main():\n",
    "    try:\n",
    "        result = divide_numbers(10, 0)  # This will raise ZeroDivisionError\n",
    "        if result is not None:\n",
    "            print(\"Result:\", result)\n",
    "        else:\n",
    "            print(\"Error occurred while dividing. Check error.log for details.\")\n",
    "    except Exception as e:\n",
    "        print(\"An error occurred:\", str(e))\n",
    "\n",
    "if __name__ == \"__main__\":\n",
    "    main()\n",
    "\n",
    "\n",
    "Explanation:\n",
    "- The `divide_numbers` function attempts to divide two numbers (`x` by `y`).\n",
    "- Inside the `try` block, it performs the division operation.\n",
    "- If the divisor (`y`) is zero, a `ZeroDivisionError` occurs, which is caught in the `except` block.\n",
    "- The exception is logged using the logging module, and `None` is returned.\n",
    "- In the `main` function, we call `divide_numbers` with a divisor of zero, triggering a `ZeroDivisionError`.\n",
    "- The error is caught, logged, and an error message is printed indicating that an error occurred while dividing.\n",
    "\n",
    "2. **OverflowError:**\n",
    "   - This error occurs when the result of an arithmetic operation exceeds the representable range of the data type.\n",
    "   - It typically occurs when performing arithmetic operations with integers that result in a value larger than the maximum representable integer.\n",
    "\n",
    "Example:\n",
    "\n",
    "import logging\n",
    "\n",
    "# Configure logging\n",
    "logging.basicConfig(filename='error.log', level=logging.ERROR)\n",
    "\n",
    "def calculate_factorial(n):\n",
    "    try:\n",
    "        factorial = 1\n",
    "        for i in range(1, n + 1):\n",
    "            factorial *= i\n",
    "        return factorial\n",
    "    except OverflowError as e:\n",
    "        logging.exception(\"Overflow occurred while calculating factorial: {}\".format(e))\n",
    "        return None\n",
    "\n",
    "def main():\n",
    "    try:\n",
    "        result = calculate_factorial(10000)  # This may raise OverflowError\n",
    "        if result is not None:\n",
    "            print(\"Factorial:\", result)\n",
    "        else:\n",
    "            print(\"Overflow occurred while calculating factorial. Check error.log for details.\")\n",
    "    except Exception as e:\n",
    "        print(\"An error occurred:\", str(e))\n",
    "\n",
    "if __name__ == \"__main__\":\n",
    "    main()\n",
    "\n",
    "\n",
    "Explanation:\n",
    "- The `calculate_factorial` function calculates the factorial of a given number `n`.\n",
    "- Inside the `try` block, it iterates over the range from 1 to `n` and calculates the factorial.\n",
    "- If the result exceeds the maximum representable integer (overflow), an `OverflowError` occurs, which is caught in the `except` block.\n",
    "- The exception is logged using the logging module, and `None` is returned.\n",
    "- In the `main` function, we call `calculate_factorial` with a large number (`10000`), which may trigger an `OverflowError`.\n",
    "- The error is caught, logged, and an error message is printed indicating that an overflow occurred while calculating the factorial.\n",
    "\n",
    "These examples demonstrate how to handle arithmetic-related errors (`ZeroDivisionError` and `OverflowError`) using the logging module to log the exceptions for further analysis and debugging."
   ]
  },
  {
   "cell_type": "markdown",
   "id": "4c58712d-7532-4ab2-b915-c17f2f868a0a",
   "metadata": {},
   "source": [
    "Q-4. Why LookupError class is used? Explain with an example KeyError and IndexError."
   ]
  },
  {
   "cell_type": "markdown",
   "id": "f3b76655-dbb5-42fb-a4ef-e2738119c4a4",
   "metadata": {},
   "source": [
    "The `LookupError` class in Python is used to indicate errors that occur when a key or index is not found in a sequence or mapping. It serves as the base class for several specific lookup-related exceptions, including `KeyError` and `IndexError`.\n",
    "\n",
    "1. **KeyError:**\n",
    "   - This error occurs when attempting to access a key in a dictionary that does not exist.\n",
    "   - It indicates that the specified key is not present in the dictionary.\n",
    "\n",
    "Example:\n",
    "\n",
    "import logging\n",
    "\n",
    "# Configure logging\n",
    "logging.basicConfig(filename='error.log', level=logging.ERROR)\n",
    "\n",
    "def access_dictionary(dictionary, key):\n",
    "    try:\n",
    "        value = dictionary[key]\n",
    "        return value\n",
    "    except KeyError as e:\n",
    "        logging.exception(\"KeyError occurred while accessing dictionary: {}\".format(e))\n",
    "        return None\n",
    "\n",
    "def main():\n",
    "    try:\n",
    "        my_dict = {'a': 1, 'b': 2, 'c': 3}\n",
    "        result = access_dictionary(my_dict, 'd')  # This will raise KeyError\n",
    "        if result is not None:\n",
    "            print(\"Value:\", result)\n",
    "        else:\n",
    "            print(\"KeyError occurred while accessing dictionary. Check error.log for details.\")\n",
    "    except Exception as e:\n",
    "        print(\"An error occurred:\", str(e))\n",
    "\n",
    "if __name__ == \"__main__\":\n",
    "    main()\n",
    "\n",
    "\n",
    "Explanation:\n",
    "- The `access_dictionary` function attempts to access a value in a dictionary using the specified key.\n",
    "- Inside the `try` block, it retrieves the value associated with the key.\n",
    "- If the key does not exist in the dictionary, a `KeyError` occurs, which is caught in the `except` block.\n",
    "- The exception is logged using the logging module, and `None` is returned.\n",
    "- In the `main` function, we call `access_dictionary` with a key (`'d'`) that does not exist in the dictionary, triggering a `KeyError`.\n",
    "- The error is caught, logged, and an error message is printed indicating that a `KeyError` occurred while accessing the dictionary.\n",
    "\n",
    "2. **IndexError:**\n",
    "   - This error occurs when attempting to access an index in a sequence (such as a list or tuple) that is out of range.\n",
    "   - It indicates that the specified index is not valid for the given sequence.\n",
    "\n",
    "Example:\n",
    "\n",
    "import logging\n",
    "\n",
    "# Configure logging\n",
    "logging.basicConfig(filename='error.log', level=logging.ERROR)\n",
    "\n",
    "def access_list(sequence, index):\n",
    "    try:\n",
    "        value = sequence[index]\n",
    "        return value\n",
    "    except IndexError as e:\n",
    "        logging.exception(\"IndexError occurred while accessing list: {}\".format(e))\n",
    "        return None\n",
    "\n",
    "def main():\n",
    "    try:\n",
    "        my_list = [1, 2, 3, 4, 5]\n",
    "        result = access_list(my_list, 10)  # This will raise IndexError\n",
    "        if result is not None:\n",
    "            print(\"Value:\", result)\n",
    "        else:\n",
    "            print(\"IndexError occurred while accessing list. Check error.log for details.\")\n",
    "    except Exception as e:\n",
    "        print(\"An error occurred:\", str(e))\n",
    "\n",
    "if __name__ == \"__main__\":\n",
    "    main()\n",
    "\n",
    "Explanation:\n",
    "- The `access_list` function attempts to access a value in a list using the specified index.\n",
    "- Inside the `try` block, it retrieves the value at the specified index.\n",
    "- If the index is out\n",
    "\n",
    "of range (i.e., greater than or equal to the length of the list), an `IndexError` occurs, which is caught in the `except` block.\n",
    "- The exception is logged using the logging module, and `None` is returned.\n",
    "- In the `main` function, we call `access_list` with an index (`10`) that is out of range for the given list, triggering an `IndexError`.\n",
    "- The error is caught, logged, and an error message is printed indicating that an `IndexError` occurred while accessing the list.\n",
    "\n",
    "In both examples, we handle lookup-related errors (`KeyError` and `IndexError`) using the logging module to log the exceptions for further analysis and debugging. This allows us to gracefully handle situations where keys or indices are not found in sequences or mappings."
   ]
  },
  {
   "cell_type": "markdown",
   "id": "c7527ca4-2443-4c1d-b13c-6c12bfcd8c98",
   "metadata": {},
   "source": [
    "Q-5. Explain ImportError. What is ModuleNotFoundError?"
   ]
  },
  {
   "cell_type": "markdown",
   "id": "7e10ebe6-4535-4492-85b3-98a462d931c3",
   "metadata": {},
   "source": [
    "`ImportError` and `ModuleNotFoundError` are both exceptions related to importing modules in Python. Let's explore each of them:\n",
    "\n",
    "1. **ImportError:**\n",
    "   - `ImportError` is raised when an imported module cannot be found, or when there is a problem with the import statement.\n",
    "   - This exception typically occurs when Python encounters an error while trying to import a module.\n",
    "   - `ImportError` can be raised for various reasons, such as:\n",
    "     - The module does not exist.\n",
    "     - The module is not installed.\n",
    "     - There is an error in the module's code.\n",
    "   - `ImportError` is a base class for more specific import-related exceptions, such as `ModuleNotFoundError` and `ImportError` (for handling errors related to importing from specific modules).\n",
    "\n",
    "2. **ModuleNotFoundError:**\n",
    "   - `ModuleNotFoundError` is a subclass of `ImportError` that specifically indicates that the requested module cannot be found.\n",
    "   - This exception was introduced in Python 3.6 to provide more specific information about import errors related to missing modules.\n",
    "   - `ModuleNotFoundError` is raised when Python cannot locate the module specified in the import statement.\n",
    "   - Prior to Python 3.6, `ImportError` was raised for all import-related errors, including cases where the module was not found. The introduction of `ModuleNotFoundError` helps in distinguishing between different types of import errors more easily.\n",
    "\n",
    "In summary, `ImportError` is a general exception raised for import-related errors, while `ModuleNotFoundError` is a more specific exception that indicates that the requested module could not be found. Both exceptions are used to handle issues related to importing modules in Python."
   ]
  },
  {
   "cell_type": "markdown",
   "id": "4a1f83ca-3f24-4aa1-aec8-245eb20587ce",
   "metadata": {},
   "source": [
    "Q-6. List down some best practices for exception handling in python."
   ]
  },
  {
   "cell_type": "markdown",
   "id": "18f39432-629b-4a3e-ae98-26eeb566ed21",
   "metadata": {},
   "source": [
    "Here are some best practices for exception handling in Python:\n",
    "\n",
    "1. **Be specific with exception handling:** Catch specific exceptions whenever possible rather than catching generic `Exception` class. This helps in identifying and handling different types of errors more effectively.\n",
    "\n",
    "2. **Use try-except blocks judiciously:** Wrap only the code that might raise an exception inside a `try` block, and catch the specific exceptions that you expect might occur in the `except` block.\n",
    "\n",
    "3. **Handle exceptions gracefully:** Handle exceptions gracefully by providing meaningful error messages or logging information to aid in debugging. This ensures that users receive helpful feedback when something goes wrong.\n",
    "\n",
    "4. **Avoid catching all exceptions:** Avoid using bare `except` blocks without specifying the exception type, as it can catch unexpected errors and make debugging more difficult. Only catch the exceptions that you expect and know how to handle.\n",
    "\n",
    "5. **Use finally block for cleanup:** Use the `finally` block to perform cleanup actions, such as closing files or releasing resources, regardless of whether an exception occurs or not. This ensures that resources are properly managed and released.\n",
    "\n",
    "6. **Keep exception handling minimal:** Keep the code inside `try` blocks minimal to reduce the chance of masking errors or unintended side effects. Only handle exceptions at the appropriate level and propagate exceptions to higher levels if necessary.\n",
    "\n",
    "7. **Use context managers (with statement):** Use context managers (e.g., `with` statement) for resource management, such as file handling or database connections. Context managers automatically handle cleanup actions even if exceptions occur.\n",
    "\n",
    "8. **Follow EAFP principle:** Follow the \"Easier to Ask for Forgiveness than Permission\" principle, which encourages trying the operation and handling the exception rather than checking for conditions beforehand. This leads to more concise and readable code.\n",
    "\n",
    "9. **Document exception handling:** Document exception handling strategies and expected exceptions in your code to make it easier for other developers (including future you) to understand and maintain the code.\n",
    "\n",
    "10. **Test exception handling:** Write unit tests to ensure that exception handling code behaves as expected under different error conditions. Test both the expected behavior when exceptions occur and when they don't.\n",
    "\n",
    "By following these best practices, you can write robust and maintainable code that handles exceptions gracefully and provides a better user experience."
   ]
  },
  {
   "cell_type": "code",
   "execution_count": null,
   "id": "09d86590-55b3-4404-a629-9d323d104592",
   "metadata": {},
   "outputs": [],
   "source": []
  }
 ],
 "metadata": {
  "kernelspec": {
   "display_name": "Python 3 (ipykernel)",
   "language": "python",
   "name": "python3"
  },
  "language_info": {
   "codemirror_mode": {
    "name": "ipython",
    "version": 3
   },
   "file_extension": ".py",
   "mimetype": "text/x-python",
   "name": "python",
   "nbconvert_exporter": "python",
   "pygments_lexer": "ipython3",
   "version": "3.10.8"
  }
 },
 "nbformat": 4,
 "nbformat_minor": 5
}
